[32m2024-02-27 00:28:07 +0200[0m - dagster - [34mDEBUG[0m - __ASSET_JOB - 28c89952-ddb2-439a-81b5-8c352d17a7dd - 9985 - LOGS_CAPTURED - Started capturing logs in process (pid: 9985).
[32m2024-02-27 00:28:07 +0200[0m - dagster - [34mDEBUG[0m - __ASSET_JOB - 28c89952-ddb2-439a-81b5-8c352d17a7dd - 9985 - airbyte_sync_5c865 - STEP_START - Started execution of step "airbyte_sync_5c865".
[32m2024-02-27 00:28:09 +0200[0m - dagster - [34mINFO[0m - __ASSET_JOB - 28c89952-ddb2-439a-81b5-8c352d17a7dd - airbyte_sync_5c865 - Job 13 initialized for connection_id=5c865c74-9da7-4528-956c-50d8c55a1f6f.
[32m2024-02-27 00:31:51 +0200[0m - dagster - [34mERROR[0m - [31m__ASSET_JOB - 28c89952-ddb2-439a-81b5-8c352d17a7dd - airbyte_sync_5c865 - Request to Airbyte API failed: 500 Server Error: Internal Server Error for url: http://localhost:8000/api/v1/jobs/cancel[0m
[32m2024-02-27 00:31:51 +0200[0m - dagster - [34mERROR[0m - [31m__ASSET_JOB - 28c89952-ddb2-439a-81b5-8c352d17a7dd - airbyte_sync_5c865 - Request to Airbyte API failed: 500 Server Error: Internal Server Error for url: http://localhost:8000/api/v1/jobs/cancel[0m
[32m2024-02-27 00:31:52 +0200[0m - dagster - [34mERROR[0m - [31m__ASSET_JOB - 28c89952-ddb2-439a-81b5-8c352d17a7dd - airbyte_sync_5c865 - Request to Airbyte API failed: 500 Server Error: Internal Server Error for url: http://localhost:8000/api/v1/jobs/cancel[0m
[32m2024-02-27 00:31:52 +0200[0m - dagster - [34mERROR[0m - [31m__ASSET_JOB - 28c89952-ddb2-439a-81b5-8c352d17a7dd - airbyte_sync_5c865 - Request to Airbyte API failed: 500 Server Error: Internal Server Error for url: http://localhost:8000/api/v1/jobs/cancel[0m
[32m2024-02-27 00:31:52 +0200[0m - dagster - [34mERROR[0m - [31m__ASSET_JOB - 28c89952-ddb2-439a-81b5-8c352d17a7dd - 9985 - airbyte_sync_5c865 - STEP_FAILURE - Execution of step "airbyte_sync_5c865" failed.

dagster._core.definitions.events.Failure: Max retries (3) exceeded with url: http://localhost:8000/api/v1/jobs/cancel.

Stack Trace:
  File "/Users/mugisha/Documents/GitHub/rembo/venv/lib/python3.9/site-packages/dagster/_core/execution/plan/execute_plan.py", line 286, in dagster_event_sequence_for_step
    for step_event in check.generator(step_events):
  File "/Users/mugisha/Documents/GitHub/rembo/venv/lib/python3.9/site-packages/dagster/_core/execution/plan/execute_step.py", line 519, in core_dagster_event_sequence_for_step
    for user_event in _step_output_error_checked_user_event_sequence(
  File "/Users/mugisha/Documents/GitHub/rembo/venv/lib/python3.9/site-packages/dagster/_core/execution/plan/execute_step.py", line 201, in _step_output_error_checked_user_event_sequence
    for user_event in user_event_sequence:
  File "/Users/mugisha/Documents/GitHub/rembo/venv/lib/python3.9/site-packages/dagster/_core/execution/plan/execute_step.py", line 99, in _process_asset_results_to_events
    for user_event in user_event_sequence:
  File "/Users/mugisha/Documents/GitHub/rembo/venv/lib/python3.9/site-packages/dagster/_core/execution/plan/compute.py", line 214, in execute_core_compute
    for step_output in _yield_compute_results(step_context, inputs, compute_fn, compute_context):
  File "/Users/mugisha/Documents/GitHub/rembo/venv/lib/python3.9/site-packages/dagster/_core/execution/plan/compute.py", line 183, in _yield_compute_results
    for event in iterate_with_context(
  File "/Users/mugisha/Documents/GitHub/rembo/venv/lib/python3.9/site-packages/dagster/_utils/__init__.py", line 467, in iterate_with_context
    next_output = next(iterator)
  File "/Users/mugisha/Documents/GitHub/rembo/venv/lib/python3.9/site-packages/dagster_airbyte/asset_defs.py", line 194, in _assets
    ab_output = airbyte.sync_and_poll(connection_id=connection_id)
  File "/Users/mugisha/Documents/GitHub/rembo/venv/lib/python3.9/site-packages/dagster_airbyte/resources.py", line 672, in sync_and_poll
    self.cancel_job(job_id)
  File "/Users/mugisha/Documents/GitHub/rembo/venv/lib/python3.9/site-packages/dagster_airbyte/resources.py", line 468, in cancel_job
    self.make_request(endpoint="/jobs/cancel", data={"id": job_id})
  File "/Users/mugisha/Documents/GitHub/rembo/venv/lib/python3.9/site-packages/dagster_airbyte/resources.py", line 465, in make_request
    raise Failure(f"Max retries ({self.request_max_retries}) exceeded with url: {url}.")

The above exception occurred during handling of the following exception:
dagster._core.definitions.events.Failure: Encountered unexpected state `failed` for job_id 13

Stack Trace:
  File "/Users/mugisha/Documents/GitHub/rembo/venv/lib/python3.9/site-packages/dagster_airbyte/resources.py", line 664, in sync_and_poll
    raise Failure(f"Encountered unexpected state `{state}` for job_id {job_id}")
[0m
